Workbook

Sheet Dashboard
A1: ICICI Bank - Retail Loan Underwriting Dashboard
A2: Sample project: 120 synthetic loan applications screened against a simple policy (income, FOIR, credit score, age). Not real bank data.
A4: Applications | C4: Requested (₹ cr) | E4: Approval rate | G4: Avg interest rate | I4: Avg FOIR | K4: Approved (₹ cr)
A5: =Summary!B11 -> 120 | C5: =Summary!C11 -> 14.791 | E5: =Summary!G11 -> 0.66666667 | G5: =Summary!H11 -> 0.10579167 | I5: =Summary!I11 -> 0.29563973 | K5: =Summary!J11 -> 9.344
A40: Quick read (auto-updates):
A41: ="- Highest approval rate: "&INDEX(Summary!A6:A10,MATCH(MAX(Summary!G6:G10),Summary!G6:G10,0))&" ("&TEXT(MAX(Summary!G6:G10),"0%")&"); lowest: "&INDEX(Summary!A6:A10,MATCH(MIN(Summary!G6:G10),Summary!G6:G10,0))&" ("&TEXT(MIN(Summary!G6:G10),"0%")&")." -> - Highest approval rate: Education Loan (100%); lowest: Business Loan (40%).
A42: ="- Most common rejection reason: "&INDEX(Summary!A18:A21,MATCH(MAX(Summary!B18:B21),Summary!B18:B21,0))&" ("&MAX(Summary!B18:B21)&" applications)." -> - Most common rejection reason: Reject - Low Score (20 applications).
A43: ="- Risk-based pricing: avg rate is "&TEXT(Summary!E27,"0.0%")&" for Poor scores vs "&TEXT(Summary!E31,"0.0%")&" for Excellent scores." -> - Risk-based pricing: avg rate is 11.3% for Poor scores vs 9.8% for Excellent scores.
A44: - Change any yellow / blue cell on the Policy sheet (e.g. max FOIR) and every table and chart refreshes.

Sheet Data
A1: App ID | B1: Customer Name | C1: City | D1: Product | E1: Age | F1: Monthly Income (₹) | G1: Credit Score | H1: Loan Amount (₹) | I1: Tenure (yrs) | J1: Existing EMI (₹) | K1: Score Band | L1: Interest Rate | M1: New EMI (₹) | N1: FOIR | O1: Max Eligible Amt (₹) | P1: Decision | R1: Note: columns A-J are sample applicant data (synthetic, randomly generated). Columns K-P are formulas driven by the Policy sheet.
A2: APP1001 | B2: Manish Mehta | C2: Mumbai | D2: Auto Loan | E2: 41 | F2: 29000 | G2: 746 | H2: 290000 | I2: 5 | J2: 3000 | K2: =INDEX(Policy!$B$13:$B$17,MATCH(G2,Policy!$A$13:$A$17,1)) -> Good | L2: =INDEX(Policy!$B$5:$B$9,MATCH(D2,Policy!$A$5:$A$9,0))+INDEX(Policy!$C$13:$C$17,MATCH(G2,Policy!$A$13:$A$17,1)) -> 0.1 | M2: =PMT(L2/12,I2*12,-H2) -> 6161.643 | N2: =(M2+J2)/F2 -> 0.31591872 | O2: =MAX(0,ROUND(PV(L2/12,I2*12,-(INDEX(Policy!$D$5:$D$9,MATCH(D2,Policy!$A$5:$A$9,0))*F2-J2)),-4)) -> 540000 | P2: =IF(G2<INDEX(Policy!$E$5:$E$9,MATCH(D2,Policy!$A$5:$A$9,0)),"Reject - Low Score",IF(E2+I2>Policy!$B$20,"Reject - Age",IF(I2>INDEX(Policy!$C$5:$C$9,MATCH(D2,Policy!$A$5:$A$9,0)),"Reject - Tenure",IF(N2<=INDEX(Policy!$D$5:$D$9,MATCH(D2,Policy!$A$5:$A$9,0)),"Approve",IF(N2<=INDEX(Policy!$D$5:$D$9,MATCH(D2,Policy!$A$5:$A$9,0))+Policy!$B$21,"Refer to Manager","Reject - High FOIR"))))) -> Approve
A3: APP1002 | B3: Pooja Patel | C3: Mumbai | D3: Business Loan | E3: 25 | F3: 100000 | G3: 761 | H3: 710000 | I3: 5 | J3: 0 | K3: =INDEX(Policy!$B$13:$B$17,MATCH(G3,Policy!$A$13:$A$17,1)) -> Very Good | L3: =INDEX(Policy!$B$5:$B$9,MATCH(D3,Policy!$A$5:$A$9,0))+INDEX(Policy!$C$13:$C$17,MATCH(G3,Policy!$A$13:$A$17,1)) -> 0.1225 | M3: =PMT(L3/12,I3*12,-H3) -> 15883.401 | N3: =(M3+J3)/F3 -> 0.15883401 | O3: =MAX(0,ROUND(PV(L3/12,I3*12,-(INDEX(Policy!$D$5:$D$9,MATCH(D3,Policy!$A$5:$A$9,0))*F3-J3)),-4)) -> 2240000 | P3: =IF(G3<INDEX(Policy!$E$5:$E$9,MATCH(D3,Policy!$A$5:$A$9,0)),"Reject - Low Score",IF(E3+I3>Policy!$B$20,"Reject - Age",IF(I3>INDEX(Policy!$C$5:$C$9,MATCH(D3,Policy!$A$5:$A$9,0)),"Reject - Tenure",IF(N3<=INDEX(Policy!$D$5:$D$9,MATCH(D3,Policy!$A$5:$A$9,0)),"Approve",IF(N3<=INDEX(Policy!$D$5:$D$9,MATCH(D3,Policy!$A$5:$A$9,0))+Policy!$B$21,"Refer to Manager","Reject - High FOIR"))))) -> Approve
A4: APP1003 | B4: Swati Mehta | C4: Bengaluru | D4: Home Loan | E4: 44 | F4: 51000 | G4: 754 | H4: 1310000 | I4: 15 | J4: 0 | K4: =INDEX(Policy!$B$13:$B$17,MATCH(G4,Policy!$A$13:$A$17,1)) -> Very Good | L4: =INDEX(Policy!$B$5:$B$9,MATCH(D4,Policy!$A$5:$A$9,0))+INDEX(Policy!$C$13:$C$17,MATCH(G4,Policy!$A$13:$A$17,1)) -> 0.09 | M4: =PMT(L4/12,I4*12,-H4) -> 13286.892 | N4: =(M4+J4)/F4 -> 0.2605273 | O4: =MAX(0,ROUND(PV(L4/12,I4*12,-(INDEX(Policy!$D$5:$D$9,MATCH(D4,Policy!$A$5:$A$9,0))*F4-J4)),-4)) -> 2510000 | P4: =IF(G4<INDEX(Policy!$E$5:$E$9,MATCH(D4,Policy!$A$5:$A$9,0)),"Reject - Low Score",IF(E4+I4>Policy!$B$20,"Reject - Age",IF(I4>INDEX(Policy!$C$5:$C$9,MATCH(D4,Policy!$A$5:$A$9,0)),"Reject - Tenure",IF(N4<=INDEX(Policy!$D$5:$D$9,MATCH(D4,Policy!$A$5:$A$9,0)),"Approve",IF(N4<=INDEX(Policy!$D$5:$D$9,MATCH(D4,Policy!$A$5:$A$9,0))+Policy!$B$21,"Refer to Manager","Reject - High FOIR"))))) -> Approve
A5: APP1004 | B5: Neha Gupta | C5: Jaipur | D5: Personal Loan | E5: 38 | F5: 93000 | G5: 714 | H5: 370000 | I5: 5 | J5: 0 | K5: =INDEX(Policy!$B$13:$B$17,MATCH(G5,Policy!$A$13:$A$17,1)) -> Good | L5: =INDEX(Policy!$B$5:$B$9,MATCH(D5,Policy!$A$5:$A$9,0))+INDEX(Policy!$C$13:$C$17,MATCH(G5,Policy!$A$13:$A$17,1)) -> 0.1225 | M5: =PMT(L5/12,I5*12,-H5) -> 8277.2652 | N5: =(M5+J5)/F5 -> 0.089002852 | O5: =MAX(0,ROUND(PV(L5/12,I5*12,-(INDEX(Policy!$D$5:$D$9,MATCH(D5,Policy!$A$5:$A$9,0))*F5-J5)),-4)) -> 1870000 | P5: =IF(G5<INDEX(Policy!$E$5:$E$9,MATCH(D5,Policy!$A$5:$A$9,0)),"Reject - Low Score",IF(E5+I5>Policy!$B$20,"Reject - Age",IF(I5>INDEX(Policy!$C$5:$C$9,MATCH(D5,Policy!$A$5:$A$9,0)),"Reject - Tenure",IF(N5<=INDEX(Policy!$D$5:$D$9,MATCH(D5,Policy!$A$5:$A$9,0)),"Approve",IF(N5<=INDEX(Policy!$D$5:$D$9,MATCH(D5,Policy!$A$5:$A$9,0))+Policy!$B$21,"Refer to Manager","Reject - High FOIR"))))) -> Reject - Low Score
A6: APP1005 | B6: Nikhil Singh | C6: Pune | D6: Home Loan | E6: 26 | F6: 42000 | G6: 712 | H6: 1280000 | I6: 10 | J6: 0 | K6: =INDEX(Policy!$B$13:$B$17,MATCH(G6,Policy!$A$13:$A$17,1)) -> Good | L6: =INDEX(Policy!$B$5:$B$9,MATCH(D6,Policy!$A$5:$A$9,0))+INDEX(Policy!$C$13:$C$17,MATCH(G6,Policy!$A$13:$A$17,1)) -> 0.095 | M6: =PMT(L6/12,I6*12,-H6) -> 16562.887 | N6: =(M6+J6)/F6 -> 0.39435446 | O6: =MAX(0,ROUND(PV(L6/12,I6*12,-(INDEX(Policy!$D$5:$D$9,MATCH(D6,Policy!$A$5:$A$9,0))*F6-J6)),-4)) -> 1620000 | P6: =IF(G6<INDEX(Policy!$E$5:$E$9,MATCH(D6,Policy!$A$5:$A$9,0)),"Reject - Low Score",IF(E6+I6>Policy!$B$20,"Reject - Age",IF(I6>INDEX(Policy!$C$5:$C$9,MATCH(D6,Policy!$A$5:$A$9,0)),"Reject - Tenure",IF(N6<=INDEX(Policy!$D$5:$D$9,MATCH(D6,Policy!$A$5:$A$9,0)),"Approve",IF(N6<=INDEX(Policy!$D$5:$D$9,MATCH(D6,Policy!$A$5:$A$9,0))+Policy!$B$21,"Refer to Manager","Reject - High FOIR"))))) -> Approve
A7: APP1006 | B7: Karan Khan | C7: Bengaluru | D7: Home Loan | E7: 42 | F7: 74000 | G7: 785 | H7: 2570000 | I7: 20 | J7: 0 | K7: =INDEX(Policy!$B$13:$B$17,MATCH(G7,Policy!$A$13:$A$17,1)) -> Very Good | L7: =INDEX(Policy!$B$5:$B$9,MATCH(D7,Policy!$A$5:$A$9,0))+INDEX(Policy!$C$13:$C$17,MATCH(G7,Policy!$A$13:$A$17,1)) -> 0.09 | M7: =PMT(L7/12,I7*12,-H7) -> 23122.957 | N7: =(M7+J7)/F7 -> 0.31247239 | O7: =MAX(0,ROUND(PV(L7/12,I7*12,-(INDEX(Policy!$D$5:$D$9,MATCH(D7,Policy!$A$5:$A$9,0))*F7-J7)),-4)) -> 4110000 | P7: =IF(G7<INDEX(Policy!$E$5:$E$9,MATCH(D7,Policy!$A$5:$A$9,0)),"Reject - Low Score",IF(E7+I7>Policy!$B$20,"Reject - Age",IF(I7>INDEX(Policy!$C$5:$C$9,MATCH(D7,Policy!$A$5:$A$9,0)),"Reject - Tenure",IF(N7<=INDEX(Policy!$D$5:$D$9,MATCH(D7,Policy!$A$5:$A$9,0)),"Approve",IF(N7<=INDEX(Policy!$D$5:$D$9,MATCH(D7,Policy!$A$5:$A$9,0))+Policy!$B$21,"Refer to Manager","Reject - High FOIR"))))) -> Approve
A8: APP1007 | B8: Nikhil Rao | C8: Bengaluru | D8: Auto Loan | E8: 45 | F8: 44000 | G8: 813 | H8: 370000 | I8: 5 | J8: 9000 | K8: =INDEX(Policy!$B$13:$B$17,MATCH(G8,Policy!$A$13:$A$17,1)) -> Excellent | L8: =INDEX(Policy!$B$5:$B$9,MATCH(D8,Policy!$A$5:$A$9,0))+INDEX(Policy!$C$13:$C$17,MATCH(G8,Policy!$A$13:$A$17,1)) -> 0.0925 | M8: =PMT(L8/12,I8*12,-H8) -> 7725.5624 | N8: =(M8+J8)/F8 -> 0.38012642 | O8: =MAX(0,ROUND(PV(L8/12,I8*12,-(INDEX(Policy!$D$5:$D$9,MATCH(D8,Policy!$A$5:$A$9,0))*F8-J8)),-4)) -> 620000 | P8: =IF(G8<INDEX(Policy!$E$5:$E$9,MATCH(D8,Policy!$A$5:$A$9,0)),"Reject - Low Score",IF(E8+I8>Policy!$B$20,"Reject - Age",IF(I8>INDEX(Policy!$C$5:$C$9,MATCH(D8,Policy!$A$5:$A$9,0)),"Reject - Tenure",IF(N8<=INDEX(Policy!$D$5:$D$9,MATCH(D8,Policy!$A$5:$A$9,0)),"Approve",IF(N8<=INDEX(Policy!$D$5:$D$9,MATCH(D8,Policy!$A$5:$A$9,0))+Policy!$B$21,"Refer to Manager","Reject - High FOIR"))))) -> Approve
A9: APP1008 | B9: Pranav Das | C9: Delhi | D9: Home Loan | E9: 28 | F9: 71000 | G9: 772 | H9: 1480000 | I9: 30 | J9: 18000 | K9: =INDEX(Policy!$B$13:$B$17,MATCH(G9,Policy!$A$13:$A$17,1)) -> Very Good | L9: =INDEX(Policy!$B$5:$B$9,MATCH(D9,Policy!$A$5:$A$9,0))+INDEX(Policy!$C$13:$C$17,MATCH(G9,Policy!$A$13:$A$17,1)) -> 0.09 | M9: =PMT(L9/12,I9*12,-H9) -> 11908.415 | N9: =(M9+J9)/F9 -> 0.42124528 | O9: =MAX(0,ROUND(PV(L9/12,I9*12,-(INDEX(Policy!$D$5:$D$9,MATCH(D9,Policy!$A$5:$A$9,0))*F9-J9)),-4)) -> 2170000 | P9: =IF(G9<INDEX(Policy!$E$5:$E$9,MATCH(D9,Policy!$A$5:$A$9,0)),"Reject - Low Score",IF(E9+I9>Policy!$B$20,"Reject - Age",IF(I9>INDEX(Policy!$C$5:$C$9,MATCH(D9,Policy!$A$5:$A$9,0)),"Reject - Tenure",IF(N9<=INDEX(Policy!$D$5:$D$9,MATCH(D9,Policy!$A$5:$A$9,0)),"Approve",IF(N9<=INDEX(Policy!$D$5:$D$9,MATCH(D9,Policy!$A$5:$A$9,0))+Policy!$B$21,"Refer to Manager","Reject - High FOIR"))))) -> Approve
A10: APP1009 | B10: Pranav Tiwari | C10: Indore | D10: Home Loan | E10: 35 | F10: 67000 | G10: 782 | H10: 2690000 | I10: 30 | J10: 10500 | K10: =INDEX(Policy!$B$13:$B$17,MATCH(G10,Policy!$A$13:$A$17,1)) -> Very Good | L10: =INDEX(Policy!$B$5:$B$9,MATCH(D10,Policy!$A$5:$A$9,0))+INDEX(Policy!$C$13:$C$17,MATCH(G10,Policy!$A$13:$A$17,1)) -> 0.09 | M10: =PMT(L10/12,I10*12,-H10) -> 21644.348 | N10: =(M10+J10)/F10 -> 0.47976639 | O10: =MAX(0,ROUND(PV(L10/12,I10*12,-(INDEX(Policy!$D$5:$D$9,MATCH(D10,Policy!$A$5:$A$9,0))*F10-J10)),-4)) -> 2860000 | P10: =IF(G10<INDEX(Policy!$E$5:$E$9,MATCH(D10,Policy!$A$5:$A$9,0)),"Reject - Low Score",IF(E10+I10>Policy!$B$20,"Reject - Age",IF(I10>INDEX(Policy!$C$5:$C$9,MATCH(D10,Policy!$A$5:$A$9,0)),"Reject - Tenure",IF(N10<=INDEX(Policy!$D$5:$D$9,MATCH(D10,Policy!$A$5:$A$9,0)),"Approve",IF(N10<=INDEX(Policy!$D$5:$D$9,MATCH(D10,Policy!$A$5:$A$9,0))+Policy!$B$21,"Refer to Manager","Reject - High FOIR"))))) -> Approve
A11: APP1010 | B11: Amit Mehta | C11: Bengaluru | D11: Home Loan | E11: 29 | F11: 28000 | G11: 655 | H11: 510000 | I11: 20 | J11: 0 | K11: =INDEX(Policy!$B$13:$B$17,MATCH(G11,Policy!$A$13:$A$17,1)) -> Fair | L11: =INDEX(Policy!$B$5:$B$9,MATCH(D11,Policy!$A$5:$A$9,0))+INDEX(Policy!$C$13:$C$17,MATCH(G11,Policy!$A$13:$A$17,1)) -> 0.1025 | M11: =PMT(L11/12,I11*12,-H11) -> 5006.3813 | N11: =(M11+J11)/F11 -> 0.17879933 | O11: =MAX(0,ROUND(PV(L11/12,I11*12,-(INDEX(Policy!$D$5:$D$9,MATCH(D11,Policy!$A$5:$A$9,0))*F11-J11)),-4)) -> 1430000 | P11: =IF(G11<INDEX(Policy!$E$5:$E$9,MATCH(D11,Policy!$A$5:$A$9,0)),"Reject - Low Score",IF(E11+I11>Policy!$B$20,"Reject - Age",IF(I11>INDEX(Policy!$C$5:$C$9,MATCH(D11,Policy!$A$5:$A$9,0)),"Reject - Tenure",IF(N11<=INDEX(Policy!$D$5:$D$9,MATCH(D11,Policy!$A$5:$A$9,0)),"Approve",IF(N11<=INDEX(Policy!$D$5:$D$9,MATCH(D11,Policy!$A$5:$A$9,0))+Policy!$B$21,"Refer to Manager","Reject - High FOIR"))))) -> Reject - Low Score
A12: APP1011 | B12: Arjun Chauhan | C12: Hyderabad | D12: Personal Loan | E12: 47 | F12: 87000 | G12: 816 | H12: 160000 | I12: 2 | J12: 0 | K12: =INDEX(Policy!$B$13:$B$17,MATCH(G12,Policy!$A$13:$A$17,1)) -> Excellent | L12: =INDEX(Policy!$B$5:$B$9,MATCH(D12,Policy!$A$5:$A$9,0))+INDEX(Policy!$C$13:$C$17,MATCH(G12,Policy!$A$13:$A$17,1)) -> 0.115 | M12: =PMT(L12/12,I12*12,-H12) -> 7494.4504 | N12: =(M12+J12)/F12 -> 0.086143109 | O12: =MAX(0,ROUND(PV(L12/12,I12*12,-(INDEX(Policy!$D$5:$D$9,MATCH(D12,Policy!$A$5:$A$9,0))*F12-J12)),-4)) -> 840000 | P12: =IF(G12<INDEX(Policy!$E$5:$E$9,MATCH(D12,Policy!$A$5:$A$9,0)),"Reject - Low Score",IF(E12+I12>Policy!$B$20,"Reject - Age",IF(I12>INDEX(Policy!$C$5:$C$9,MATCH(D12,Policy!$A$5:$A$9,0)),"Reject - Tenure",IF(N12<=INDEX(Policy!$D$5:$D$9,MATCH(D12,Policy!$A$5:$A$9,0)),"Approve",IF(N12<=INDEX(Policy!$D$5:$D$9,MATCH(D12,Policy!$A$5:$A$9,0))+Policy!$B$21,"Refer to Manager","Reject - High FOIR"))))) -> Approve
A13: APP1012 | B13: Swati Jain | C13: Delhi | D13: Auto Loan | E13: 30 | F13: 67000 | G13: 651 | H13: 540000 | I13: 5 | J13: 4500 | K13: =INDEX(Policy!$B$13:$B$17,MATCH(G13,Policy!$A$13:$A$17,1)) -> Fair | L13: =INDEX(Policy!$B$5:$B$9,MATCH(D13,Policy!$A$5:$A$9,0))+INDEX(Policy!$C$13:$C$17,MATCH(G13,Policy!$A$13:$A$17,1)) -> 0.1075 | M13: =PMT(L13/12,I13*12,-H13) -> 11673.695 | N13: =(M13+J13)/F13 -> 0.24139843 | O13: =MAX(0,ROUND(PV(L13/12,I13*12,-(INDEX(Policy!$D$5:$D$9,MATCH(D13,Policy!$A$5:$A$9,0))*F13-J13)),-4)) -> 1340000 | P13: =IF(G13<INDEX(Policy!$E$5:$E$9,MATCH(D13,Policy!$A$5:$A$9,0)),"Reject - Low Score",IF(E13+I13>Policy!$B$20,"Reject - Age",IF(I13>INDEX(Policy!$C$5:$C$9,MATCH(D13,Policy!$A$5:$A$9,0)),"Reject - Tenure",IF(N13<=INDEX(Policy!$D$5:$D$9,MATCH(D13,Policy!$A$5:$A$9,0)),"Approve",IF(N13<=INDEX(Policy!$D$5:$D$9,MATCH(D13,Policy!$A$5:$A$9,0))+Policy!$B$21,"Refer to Manager","Reject - High FOIR"))))) -> Reject - Low Score
... A121: APP1120 | B121: Harsh Verma | C121: Mumbai | D121: Home Loan | E121: 33 | F121: 135000 | G121: 774 | H121: 3180000 | I121: 20 | J121: 0 | K121: =INDEX(Policy!$B$13:$B$17,MATCH(G121,Policy!$A$13:$A$17,1)) -> Very Good | L121: =INDEX(Policy!$B$5:$B$9,MATCH(D121,Policy!$A$5:$A$9,0))+INDEX(Policy!$C$13:$C$17,MATCH(G121,Policy!$A$13:$A$17,1)) -> 0.09 | M121: =PMT(L121/12,I121*12,-H121) -> 28611.285 | N121: =(M121+J121)/F121 -> 0.21193545 | O121: =MAX(0,ROUND(PV(L121/12,I121*12,-(INDEX(Policy!$D$5:$D$9,MATCH(D121,Policy!$A$5:$A$9,0))*F121-J121)),-4)) -> 7500000 | P121: =IF(G121<INDEX(Policy!$E$5:$E$9,MATCH(D121,Policy!$A$5:$A$9,0)),"Reject - Low Score",IF(E121+I121>Policy!$B$20,"Reject - Age",IF(I121>INDEX(Policy!$C$5:$C$9,MATCH(D121,Policy!$A$5:$A$9,0)),"Reject - Tenure",IF(N121<=INDEX(Policy!$D$5:$D$9,MATCH(D121,Policy!$A$5:$A$9,0)),"Approve",IF(N121<=INDEX(Policy!$D$5:$D$9,MATCH(D121,Policy!$A$5:$A$9,0))+Policy!$B$21,"Refer to Manager","Reject - High FOIR"))))) -> Approve

Sheet Policy
A1: Lending Policy (assumptions)
A2: Illustrative policy used for this project - NOT ICICI Bank's actual rate card or credit policy. Change the blue cells and everything updates.
A4: Product | B4: Base Rate (p.a.) | C4: Max Tenure (yrs) | D4: Max FOIR | E4: Min Credit Score
A5: Home Loan | B5: 0.0875 | C5: 30 | D5: 0.5 | E5: 700
A6: Auto Loan | B6: 0.0925 | C6: 7 | D6: 0.5 | E6: 690
A7: Personal Loan | B7: 0.115 | C7: 5 | D7: 0.45 | E7: 720
A8: Education Loan | B8: 0.095 | C8: 15 | D8: 0.55 | E8: 650
A9: Business Loan | B9: 0.12 | C9: 7 | D9: 0.5 | E9: 700
A12: Min Score | B12: Score Band | C12: Rate Premium
A13: 0 | B13: Poor | C13: 0.025
A14: 650 | B14: Fair | C14: 0.015
A15: 700 | B15: Good | C15: 0.0075
A16: 750 | B16: Very Good | C16: 0.0025
A17: 800 | B17: Excellent | C17: 0
A20: Max age at loan maturity | B20: 65
A21: Refer-to-manager buffer over max FOIR | B21: 0.05
A23: FOIR = (new EMI + existing EMIs) / monthly income. Final rate = base rate of product + premium for the applicant's score band.

Sheet Summary
A1: Summary Tables
A2: Everything here is COUNTIFS / SUMIFS / AVERAGEIFS on the Data sheet, so it refreshes when Data or Policy changes. Amounts in ₹ crore.
A4: 1. Product-wise
A5: Product | B5: Applications | C5: Requested (₹ cr) | D5: Approved | E5: Referred | F5: Rejected | G5: Approval % | H5: Avg Rate | I5: Avg FOIR | J5: Approved Amt (₹ cr)
A6: =Policy!A5 -> Home Loan | B6: =COUNTIF(Data!$D$2:$D$121,A6) -> 38 | C6: =SUMIF(Data!$D$2:$D$121,A6,Data!$H$2:$H$121)/10000000 -> 8.739 | D6: =COUNTIFS(Data!$D$2:$D$121,A6,Data!$P$2:$P$121,"Approve") -> 19 | E6: =COUNTIFS(Data!$D$2:$D$121,A6,Data!$P$2:$P$121,"Refer to Manager") -> 4 | F6: =B6-D6-E6 -> 15 | G6: =IF(B6=0,0,D6/B6) -> 0.5 | H6: =IFERROR(AVERAGEIF(Data!$D$2:$D$121,A6,Data!$L$2:$L$121),0) -> 0.093092105 | I6: =IFERROR(AVERAGEIF(Data!$D$2:$D$121,A6,Data!$N$2:$N$121),0) -> 0.36062086 | J6: =SUMIFS(Data!$H$2:$H$121,Data!$D$2:$D$121,A6,Data!$P$2:$P$121,"Approve")/10000000 -> 4.692
A7: =Policy!A6 -> Auto Loan | B7: =COUNTIF(Data!$D$2:$D$121,A7) -> 27 | C7: =SUMIF(Data!$D$2:$D$121,A7,Data!$H$2:$H$121)/10000000 -> 1.641 | D7: =COUNTIFS(Data!$D$2:$D$121,A7,Data!$P$2:$P$121,"Approve") -> 25 | E7: =COUNTIFS(Data!$D$2:$D$121,A7,Data!$P$2:$P$121,"Refer to Manager") -> 0 | F7: =B7-D7-E7 -> 2 | G7: =IF(B7=0,0,D7/B7) -> 0.92592593 | H7: =IFERROR(AVERAGEIF(Data!$D$2:$D$121,A7,Data!$L$2:$L$121),0) -> 0.097407407 | I7: =IFERROR(AVERAGEIF(Data!$D$2:$D$121,A7,Data!$N$2:$N$121),0) -> 0.26133086 | J7: =SUMIFS(Data!$H$2:$H$121,Data!$D$2:$D$121,A7,Data!$P$2:$P$121,"Approve")/10000000 -> 1.477
A8: =Policy!A7 -> Personal Loan | B8: =COUNTIF(Data!$D$2:$D$121,A8) -> 27 | C8: =SUMIF(Data!$D$2:$D$121,A8,Data!$H$2:$H$121)/10000000 -> 0.816 | D8: =COUNTIFS(Data!$D$2:$D$121,A8,Data!$P$2:$P$121,"Approve") -> 17 | E8: =COUNTIFS(Data!$D$2:$D$121,A8,Data!$P$2:$P$121,"Refer to Manager") -> 0 | F8: =B8-D8-E8 -> 10 | G8: =IF(B8=0,0,D8/B8) -> 0.62962963 | H8: =IFERROR(AVERAGEIF(Data!$D$2:$D$121,A8,Data!$L$2:$L$121),0) -> 0.12185185 | I8: =IFERROR(AVERAGEIF(Data!$D$2:$D$121,A8,Data!$N$2:$N$121),0) -> 0.15900432 | J8: =SUMIFS(Data!$H$2:$H$121,Data!$D$2:$D$121,A8,Data!$P$2:$P$121,"Approve")/10000000 -> 0.527
A9: =Policy!A8 -> Education Loan | B9: =COUNTIF(Data!$D$2:$D$121,A9) -> 13 | C9: =SUMIF(Data!$D$2:$D$121,A9,Data!$H$2:$H$121)/10000000 -> 1.523 | D9: =COUNTIFS(Data!$D$2:$D$121,A9,Data!$P$2:$P$121,"Approve") -> 13 | E9: =COUNTIFS(Data!$D$2:$D$121,A9,Data!$P$2:$P$121,"Refer to Manager") -> 0 | F9: =B9-D9-E9 -> 0 | G9: =IF(B9=0,0,D9/B9) -> 1 | H9: =IFERROR(AVERAGEIF(Data!$D$2:$D$121,A9,Data!$L$2:$L$121),0) -> 0.10288462 | I9: =IFERROR(AVERAGEIF(Data!$D$2:$D$121,A9,Data!$N$2:$N$121),0) -> 0.26717185 | J9: =SUMIFS(Data!$H$2:$H$121,Data!$D$2:$D$121,A9,Data!$P$2:$P$121,"Approve")/10000000 -> 1.523
A10: =Policy!A9 -> Business Loan | B10: =COUNTIF(Data!$D$2:$D$121,A10) -> 15 | C10: =SUMIF(Data!$D$2:$D$121,A10,Data!$H$2:$H$121)/10000000 -> 2.072 | D10: =COUNTIFS(Data!$D$2:$D$121,A10,Data!$P$2:$P$121,"Approve") -> 6 | E10: =COUNTIFS(Data!$D$2:$D$121,A10,Data!$P$2:$P$121,"Refer to Manager") -> 1 | F10: =B10-D10-E10 -> 8 | G10: =IF(B10=0,0,D10/B10) -> 0.4 | H10: =IFERROR(AVERAGEIF(Data!$D$2:$D$121,A10,Data!$L$2:$L$121),0) -> 0.12666667 | I10: =IFERROR(AVERAGEIF(Data!$D$2:$D$121,A10,Data!$N$2:$N$121),0) -> 0.46339269 | J10: =SUMIFS(Data!$H$2:$H$121,Data!$D$2:$D$121,A10,Data!$P$2:$P$121,"Approve")/10000000 -> 1.125
A11: Total | B11: =SUM(B6:B10) -> 120 | C11: =SUM(C6:C10) -> 14.791 | D11: =SUM(D6:D10) -> 80 | E11: =SUM(E6:E10) -> 5 | F11: =SUM(F6:F10) -> 35 | G11: =IF(B11=0,0,D11/B11) -> 0.66666667 | H11: =AVERAGE(Data!$L$2:$L$121) -> 0.10579167 | I11: =AVERAGE(Data!$N$2:$N$121) -> 0.29563973 | J11: =SUM(J6:J10) -> 9.344
A14: 2. Decision breakdown
A15: Decision | B15: Count | C15: % of total
A16: Approve | B16: =COUNTIF(Data!$P$2:$P$121,A16) -> 80 | C16: =B16/$B$22 -> 0.66666667
A17: Refer to Manager | B17: =COUNTIF(Data!$P$2:$P$121,A17) -> 5 | C17: =B17/$B$22 -> 0.041666667
A18: Reject - Low Score | B18: =COUNTIF(Data!$P$2:$P$121,A18) -> 20 | C18: =B18/$B$22 -> 0.16666667
A19: Reject - Age | B19: =COUNTIF(Data!$P$2:$P$121,A19) -> 5 | C19: =B19/$B$22 -> 0.041666667
A20: Reject - Tenure | B20: =COUNTIF(Data!$P$2:$P$121,A20) -> 0 | C20: =B20/$B$22 -> 0
A21: Reject - High FOIR | B21: =COUNTIF(Data!$P$2:$P$121,A21) -> 10 | C21: =B21/$B$22 -> 0.083333333
A22: Total | B22: =SUM(B16:B21) -> 120 | C22: =SUM(C16:C21) -> 1 | D22: =IF(B22=COUNTA(Data!$A$2:$A$121),"ties to Data","CHECK - count mismatch") -> ties to Data
A25: 3. Credit score band (risk-based pricing check)
A26: Score Band | B26: Applications | C26: Approved | D26: Approval % | E26: Avg Rate
A27: =Policy!B13 -> Poor | B27: =COUNTIF(Data!$K$2:$K$121,A27) -> 1 | C27: =COUNTIFS(Data!$K$2:$K$121,A27,Data!$P$2:$P$121,"Approve") -> 0 | D27: =IF(B27=0,0,C27/B27) -> 0 | E27: =IFERROR(AVERAGEIF(Data!$K$2:$K$121,A27,Data!$L$2:$L$121),0) -> 0.1125
A28: =Policy!B14 -> Fair | B28: =COUNTIF(Data!$K$2:$K$121,A28) -> 19 | C28: =COUNTIFS(Data!$K$2:$K$121,A28,Data!$P$2:$P$121,"Approve") -> 5 | D28: =IF(B28=0,0,C28/B28) -> 0.26315789 | E28: =IFERROR(AVERAGEIF(Data!$K$2:$K$121,A28,Data!$L$2:$L$121),0) -> 0.11723684
A29: =Policy!B15 -> Good | B29: =COUNTIF(Data!$K$2:$K$121,A29) -> 42 | C29: =COUNTIFS(Data!$K$2:$K$121,A29,Data!$P$2:$P$121,"Approve") -> 30 | D29: =IF(B29=0,0,C29/B29) -> 0.71428571 | E29: =IFERROR(AVERAGEIF(Data!$K$2:$K$121,A29,Data!$L$2:$L$121),0) -> 0.10928571
A30: =Policy!B16 -> Very Good | B30: =COUNTIF(Data!$K$2:$K$121,A30) -> 43 | C30: =COUNTIFS(Data!$K$2:$K$121,A30,Data!$P$2:$P$121,"Approve") -> 34 | D30: =IF(B30=0,0,C30/B30) -> 0.79069767 | E30: =IFERROR(AVERAGEIF(Data!$K$2:$K$121,A30,Data!$L$2:$L$121),0) -> 0.09994186
A31: =Policy!B17 -> Excellent | B31: =COUNTIF(Data!$K$2:$K$121,A31) -> 15 | C31: =COUNTIFS(Data!$K$2:$K$121,A31,Data!$P$2:$P$121,"Approve") -> 11 | D31: =IF(B31=0,0,C31/B31) -> 0.73333333 | E31: =IFERROR(AVERAGEIF(Data!$K$2:$K$121,A31,Data!$L$2:$L$121),0) -> 0.097833333
A34: 4. City-wise
A35: City | B35: Applications | C35: Requested (₹ cr) | D35: Approved | E35: Approval %
A36: Mumbai | B36: =COUNTIF(Data!$C$2:$C$121,A36) -> 23 | C36: =SUMIF(Data!$C$2:$C$121,A36,Data!$H$2:$H$121)/10000000 -> 3.327 | D36: =COUNTIFS(Data!$C$2:$C$121,A36,Data!$P$2:$P$121,"Approve") -> 15 | E36: =IF(B36=0,0,D36/B36) -> 0.65217391
A37: Delhi | B37: =COUNTIF(Data!$C$2:$C$121,A37) -> 11 | C37: =SUMIF(Data!$C$2:$C$121,A37,Data!$H$2:$H$121)/10000000 -> 1.601 | D37: =COUNTIFS(Data!$C$2:$C$121,A37,Data!$P$2:$P$121,"Approve") -> 5 | E37: =IF(B37=0,0,D37/B37) -> 0.45454545
A38: Bengaluru | B38: =COUNTIF(Data!$C$2:$C$121,A38) -> 24 | C38: =SUMIF(Data!$C$2:$C$121,A38,Data!$H$2:$H$121)/10000000 -> 2.532 | D38: =COUNTIFS(Data!$C$2:$C$121,A38,Data!$P$2:$P$121,"Approve") -> 17 | E38: =IF(B38=0,0,D38/B38) -> 0.70833333
A39: Hyderabad | B39: =COUNTIF(Data!$C$2:$C$121,A39) -> 13 | C39: =SUMIF(Data!$C$2:$C$121,A39,Data!$H$2:$H$121)/10000000 -> 1.337 | D39: =COUNTIFS(Data!$C$2:$C$121,A39,Data!$P$2:$P$121,"Approve") -> 10 | E39: =IF(B39=0,0,D39/B39) -> 0.76923077
A40: Pune | B40: =COUNTIF(Data!$C$2:$C$121,A40) -> 10 | C40: =SUMIF(Data!$C$2:$C$121,A40,Data!$H$2:$H$121)/10000000 -> 0.714 | D40: =COUNTIFS(Data!$C$2:$C$121,A40,Data!$P$2:$P$121,"Approve") -> 10 | E40: =IF(B40=0,0,D40/B40) -> 1
A41: Chennai | B41: =COUNTIF(Data!$C$2:$C$121,A41) -> 3 | C41: =SUMIF(Data!$C$2:$C$121,A41,Data!$H$2:$H$121)/10000000 -> 0.338 | D41: =COUNTIFS(Data!$C$2:$C$121,A41,Data!$P$2:$P$121,"Approve") -> 1 | E41: =IF(B41=0,0,D41/B41) -> 0.33333333
A42: Kolkata | B42: =COUNTIF(Data!$C$2:$C$121,A42) -> 5 | C42: =SUMIF(Data!$C$2:$C$121,A42,Data!$H$2:$H$121)/10000000 -> 0.428 | D42: =COUNTIFS(Data!$C$2:$C$121,A42,Data!$P$2:$P$121,"Approve") -> 3 | E42: =IF(B42=0,0,D42/B42) -> 0.6
A43: Bhopal | B43: =COUNTIF(Data!$C$2:$C$121,A43) -> 9 | C43: =SUMIF(Data!$C$2:$C$121,A43,Data!$H$2:$H$121)/10000000 -> 1.642 | D43: =COUNTIFS(Data!$C$2:$C$121,A43,Data!$P$2:$P$121,"Approve") -> 5 | E43: =IF(B43=0,0,D43/B43) -> 0.55555556
A44: Indore | B44: =COUNTIF(Data!$C$2:$C$121,A44) -> 12 | C44: =SUMIF(Data!$C$2:$C$121,A44,Data!$H$2:$H$121)/10000000 -> 2.022 | D44: =COUNTIFS(Data!$C$2:$C$121,A44,Data!$P$2:$P$121,"Approve") -> 8 | E44: =IF(B44=0,0,D44/B44) -> 0.66666667
A45: Jaipur | B45: =COUNTIF(Data!$C$2:$C$121,A45) -> 10 | C45: =SUMIF(Data!$C$2:$C$121,A45,Data!$H$2:$H$121)/10000000 -> 0.85 | D45: =COUNTIFS(Data!$C$2:$C$121,A45,Data!$P$2:$P$121,"Approve") -> 6 | E45: =IF(B45=0,0,D45/B45) -> 0.6

Sheet EMI_Calculator
A1: EMI Calculator + Amortisation Schedule
A2: Pick a product and fill the yellow cells. Rate comes from the Policy sheet (base rate + score-band premium).
A4: Product | B4: Home Loan | D4: Interest rate (p.a.) | E4: =INDEX(Policy!$B$5:$B$9,MATCH(B4,Policy!$A$5:$A$9,0))+INDEX(Policy!$C$13:$C$17,MATCH(B7,Policy!$A$13:$A$17,1)) -> 0.095
A5: Loan amount (₹) | B5: 5000000 | D5: Monthly EMI (₹) | E5: =PMT(E4/12,B6*12,-B5) -> 46606.559
A6: Tenure (years) | B6: 20 | D6: Total interest (₹) | E6: =E5*B6*12-B5 -> 6185574.3
A7: Credit score | B7: 745 | D7: Total payment (₹) | E7: =E5*B6*12 -> 11185574
D8: Interest as % of loan | E8: =E6/B5 -> 1.2371149
D9: Tenure allowed by policy? | E9: =IF(B6<=INDEX(Policy!$C$5:$C$9,MATCH(B4,Policy!$A$5:$A$9,0)),"Yes","No - exceeds max tenure") -> Yes
A11: Yearly view
A12: Year | B12: Principal paid (₹) | C12: Interest paid (₹) | D12: Closing balance (₹) | G12: Month | H12: Year | I12: Opening Bal (₹) | J12: EMI (₹) | K12: Interest (₹) | L12: Principal (₹) | M12: Closing Bal (₹)
A13: =IF(1<=$B$6,1,"") -> 1 | B13: =IF(A13="","",SUMIF($H$13:$H$372,A13,$L$13:$L$372)) -> 88046.933 | C13: =IF(A13="","",SUMIF($H$13:$H$372,A13,$K$13:$K$372)) -> 471231.78 | D13: =IF(A13="","",INDEX($M$13:$M$372,A13*12)) -> 4911953.1 | G13: =IF(1<=$B$6*12,1,"") -> 1 | H13: =IF(G13="","",ROUNDUP(G13/12,0)) -> 1 | I13: =IF(G13="","",$B$5) -> 5000000 | J13: =IF(G13="","",$E$5) -> 46606.559 | K13: =IF(G13="","",I13*$E$4/12) -> 39583.333 | L13: =IF(G13="","",J13-K13) -> 7023.2261 | M13: =IF(G13="","",MAX(0,I13-L13)) -> 4992976.8
A14: =IF(2<=$B$6,2,"") -> 2 | B14: =IF(A14="","",SUMIF($H$13:$H$372,A14,$L$13:$L$372)) -> 96785.378 | C14: =IF(A14="","",SUMIF($H$13:$H$372,A14,$K$13:$K$372)) -> 462493.33 | D14: =IF(A14="","",INDEX($M$13:$M$372,A14*12)) -> 4815167.7 | G14: =IF(2<=$B$6*12,2,"") -> 2 | H14: =IF(G14="","",ROUNDUP(G14/12,0)) -> 1 | I14: =IF(G14="","",M13) -> 4992976.8 | J14: =IF(G14="","",$E$5) -> 46606.559 | K14: =IF(G14="","",I14*$E$4/12) -> 39527.733 | L14: =IF(G14="","",J14-K14) -> 7078.8266 | M14: =IF(G14="","",MAX(0,I14-L14)) -> 4985897.9
A15: =IF(3<=$B$6,3,"") -> 3 | B15: =IF(A15="","",SUMIF($H$13:$H$372,A15,$L$13:$L$372)) -> 106391.09 | C15: =IF(A15="","",SUMIF($H$13:$H$372,A15,$K$13:$K$372)) -> 452887.62 | D15: =IF(A15="","",INDEX($M$13:$M$372,A15*12)) -> 4708776.6 | G15: =IF(3<=$B$6*12,3,"") -> 3 | H15: =IF(G15="","",ROUNDUP(G15/12,0)) -> 1 | I15: =IF(G15="","",M14) -> 4985897.9 | J15: =IF(G15="","",$E$5) -> 46606.559 | K15: =IF(G15="","",I15*$E$4/12) -> 39471.692 | L15: =IF(G15="","",J15-K15) -> 7134.8673 | M15: =IF(G15="","",MAX(0,I15-L15)) -> 4978763.1
A16: =IF(4<=$B$6,4,"") -> 4 | B16: =IF(A16="","",SUMIF($H$13:$H$372,A16,$L$13:$L$372)) -> 116950.15 | C16: =IF(A16="","",SUMIF($H$13:$H$372,A16,$K$13:$K$372)) -> 442328.56 | D16: =IF(A16="","",INDEX($M$13:$M$372,A16*12)) -> 4591826.4 | G16: =IF(4<=$B$6*12,4,"") -> 4 | H16: =IF(G16="","",ROUNDUP(G16/12,0)) -> 1 | I16: =IF(G16="","",M15) -> 4978763.1 | J16: =IF(G16="","",$E$5) -> 46606.559 | K16: =IF(G16="","",I16*$E$4/12) -> 39415.208 | L16: =IF(G16="","",J16-K16) -> 7191.3517 | M16: =IF(G16="","",MAX(0,I16-L16)) -> 4971571.7
A17: =IF(5<=$B$6,5,"") -> 5 | B17: =IF(A17="","",SUMIF($H$13:$H$372,A17,$L$13:$L$372)) -> 128557.17 | C17: =IF(A17="","",SUMIF($H$13:$H$372,A17,$K$13:$K$372)) -> 430721.54 | D17: =IF(A17="","",INDEX($M$13:$M$372,A17*12)) -> 4463269.3 | G17: =IF(5<=$B$6*12,5,"") -> 5 | H17: =IF(G17="","",ROUNDUP(G17/12,0)) -> 1 | I17: =IF(G17="","",M16) -> 4971571.7 | J17: =IF(G17="","",$E$5) -> 46606.559 | K17: =IF(G17="","",I17*$E$4/12) -> 39358.276 | L17: =IF(G17="","",J17-K17) -> 7248.2832 | M17: =IF(G17="","",MAX(0,I17-L17)) -> 4964323.4
A18: =IF(6<=$B$6,6,"") -> 6 | B18: =IF(A18="","",SUMIF($H$13:$H$372,A18,$L$13:$L$372)) -> 141316.16 | C18: =IF(A18="","",SUMIF($H$13:$H$372,A18,$K$13:$K$372)) -> 417962.55 | D18: =IF(A18="","",INDEX($M$13:$M$372,A18*12)) -> 4321953.1 | G18: =IF(6<=$B$6*12,6,"") -> 6 | H18: =IF(G18="","",ROUNDUP(G18/12,0)) -> 1 | I18: =IF(G18="","",M17) -> 4964323.4 | J18: =IF(G18="","",$E$5) -> 46606.559 | K18: =IF(G18="","",I18*$E$4/12) -> 39300.894 | L18: =IF(G18="","",J18-K18) -> 7305.6655 | M18: =IF(G18="","",MAX(0,I18-L18)) -> 4957017.8
A19: =IF(7<=$B$6,7,"") -> 7 | B19: =IF(A19="","",SUMIF($H$13:$H$372,A19,$L$13:$L$372)) -> 155341.45 | C19: =IF(A19="","",SUMIF($H$13:$H$372,A19,$K$13:$K$372)) -> 403937.26 | D19: =IF(A19="","",INDEX($M$13:$M$372,A19*12)) -> 4166611.7 | G19: =IF(7<=$B$6*12,7,"") -> 7 | H19: =IF(G19="","",ROUNDUP(G19/12,0)) -> 1 | I19: =IF(G19="","",M18) -> 4957017.8 | J19: =IF(G19="","",$E$5) -> 46606.559 | K19: =IF(G19="","",I19*$E$4/12) -> 39243.057 | L19: =IF(G19="","",J19-K19) -> 7363.502 | M19: =IF(G19="","",MAX(0,I19-L19)) -> 4949654.3
A20: =IF(8<=$B$6,8,"") -> 8 | B20: =IF(A20="","",SUMIF($H$13:$H$372,A20,$L$13:$L$372)) -> 170758.71 | C20: =IF(A20="","",SUMIF($H$13:$H$372,A20,$K$13:$K$372)) -> 388520 | D20: =IF(A20="","",INDEX($M$13:$M$372,A20*12)) -> 3995852.9 | G20: =IF(8<=$B$6*12,8,"") -> 8 | H20: =IF(G20="","",ROUNDUP(G20/12,0)) -> 1 | I20: =IF(G20="","",M19) -> 4949654.3 | J20: =IF(G20="","",$E$5) -> 46606.559 | K20: =IF(G20="","",I20*$E$4/12) -> 39184.763 | L20: =IF(G20="","",J20-K20) -> 7421.7964 | M20: =IF(G20="","",MAX(0,I20-L20)) -> 4942232.5
A21: =IF(9<=$B$6,9,"") -> 9 | B21: =IF(A21="","",SUMIF($H$13:$H$372,A21,$L$13:$L$372)) -> 187706.1 | C21: =IF(A21="","",SUMIF($H$13:$H$372,A21,$K$13:$K$372)) -> 371572.61 | D21: =IF(A21="","",INDEX($M$13:$M$372,A21*12)) -> 3808146.8 | G21: =IF(9<=$B$6*12,9,"") -> 9 | H21: =IF(G21="","",ROUNDUP(G21/12,0)) -> 1 | I21: =IF(G21="","",M20) -> 4942232.5 | J21: =IF(G21="","",$E$5) -> 46606.559 | K21: =IF(G21="","",I21*$E$4/12) -> 39126.007 | L21: =IF(G21="","",J21-K21) -> 7480.5522 | M21: =IF(G21="","",MAX(0,I21-L21)) -> 4934751.9
A22: =IF(10<=$B$6,10,"") -> 10 | B22: =IF(A22="","",SUMIF($H$13:$H$372,A22,$L$13:$L$372)) -> 206335.48 | C22: =IF(A22="","",SUMIF($H$13:$H$372,A22,$K$13:$K$372)) -> 352943.23 | D22: =IF(A22="","",INDEX($M$13:$M$372,A22*12)) -> 3601811.4 | G22: =IF(10<=$B$6*12,10,"") -> 10 | H22: =IF(G22="","",ROUNDUP(G22/12,0)) -> 1 | I22: =IF(G22="","",M21) -> 4934751.9 | J22: =IF(G22="","",$E$5) -> 46606.559 | K22: =IF(G22="","",I22*$E$4/12) -> 39066.786 | L22: =IF(G22="","",J22-K22) -> 7539.7733 | M22: =IF(G22="","",MAX(0,I22-L22)) -> 4927212.2
A23: =IF(11<=$B$6,11,"") -> 11 | B23: =IF(A23="","",SUMIF($H$13:$H$372,A23,$L$13:$L$372)) -> 226813.78 | C23: =IF(A23="","",SUMIF($H$13:$H$372,A23,$K$13:$K$372)) -> 332464.94 | D23: =IF(A23="","",INDEX($M$13:$M$372,A23*12)) -> 3374997.6 | G23: =IF(11<=$B$6*12,11,"") -> 11 | H23: =IF(G23="","",ROUNDUP(G23/12,0)) -> 1 | I23: =IF(G23="","",M22) -> 4927212.2 | J23: =IF(G23="","",$E$5) -> 46606.559 | K23: =IF(G23="","",I23*$E$4/12) -> 39007.096 | L23: =IF(G23="","",J23-K23) -> 7599.4632 | M23: =IF(G23="","",MAX(0,I23-L23)) -> 4919612.7
A24: =IF(12<=$B$6,12,"") -> 12 | B24: =IF(A24="","",SUMIF($H$13:$H$372,A24,$L$13:$L$372)) -> 249324.5 | C24: =IF(A24="","",SUMIF($H$13:$H$372,A24,$K$13:$K$372)) -> 309954.22 | D24: =IF(A24="","",INDEX($M$13:$M$372,A24*12)) -> 3125673.1 | G24: =IF(12<=$B$6*12,12,"") -> 12 | H24: =IF(G24="","",ROUNDUP(G24/12,0)) -> 1 | I24: =IF(G24="","",M23) -> 4919612.7 | J24: =IF(G24="","",$E$5) -> 46606.559 | K24: =IF(G24="","",I24*$E$4/12) -> 38946.934 | L24: =IF(G24="","",J24-K24) -> 7659.6256 | M24: =IF(G24="","",MAX(0,I24-L24)) -> 4911953.1
A25: =IF(13<=$B$6,13,"") -> 13 | B25: =IF(A25="","",SUMIF($H$13:$H$372,A25,$L$13:$L$372)) -> 274069.35 | C25: =IF(A25="","",SUMIF($H$13:$H$372,A25,$K$13:$K$372)) -> 285209.36 | D25: =IF(A25="","",INDEX($M$13:$M$372,A25*12)) -> 2851603.7 | G25: =IF(13<=$B$6*12,13,"") -> 13 | H25: =IF(G25="","",ROUNDUP(G25/12,0)) -> 2 | I25: =IF(G25="","",M24) -> 4911953.1 | J25: =IF(G25="","",$E$5) -> 46606.559 | K25: =IF(G25="","",I25*$E$4/12) -> 38886.295 | L25: =IF(G25="","",J25-K25) -> 7720.2643 | M25: =IF(G25="","",MAX(0,I25-L25)) -> 4904232.8
A26: =IF(14<=$B$6,14,"") -> 14 | B26: =IF(A26="","",SUMIF($H$13:$H$372,A26,$L$13:$L$372)) -> 301270.07 | C26: =IF(A26="","",SUMIF($H$13:$H$372,A26,$K$13:$K$372)) -> 258008.64 | D26: =IF(A26="","",INDEX($M$13:$M$372,A26*12)) -> 2550333.7 | G26: =IF(14<=$B$6*12,14,"") -> 14 | H26: =IF(G26="","",ROUNDUP(G26/12,0)) -> 2 | I26: =IF(G26="","",M25) -> 4904232.8 | J26: =IF(G26="","",$E$5) -> 46606.559 | K26: =IF(G26="","",I26*$E$4/12) -> 38825.176 | L26: =IF(G26="","",J26-K26) -> 7781.383 | M26: =IF(G26="","",MAX(0,I26-L26)) -> 4896451.4
A27: =IF(15<=$B$6,15,"") -> 15 | B27: =IF(A27="","",SUMIF($H$13:$H$372,A27,$L$13:$L$372)) -> 331170.4 | C27: =IF(A27="","",SUMIF($H$13:$H$372,A27,$K$13:$K$372)) -> 228108.32 | D27: =IF(A27="","",INDEX($M$13:$M$372,A27*12)) -> 2219163.3 | G27: =IF(15<=$B$6*12,15,"") -> 15 | H27: =IF(G27="","",ROUNDUP(G27/12,0)) -> 2 | I27: =IF(G27="","",M26) -> 4896451.4 | J27: =IF(G27="","",$E$5) -> 46606.559 | K27: =IF(G27="","",I27*$E$4/12) -> 38763.574 | L27: =IF(G27="","",J27-K27) -> 7842.9857 | M27: =IF(G27="","",MAX(0,I27-L27)) -> 4888608.4
A28: =IF(16<=$B$6,16,"") -> 16 | B28: =IF(A28="","",SUMIF($H$13:$H$372,A28,$L$13:$L$372)) -> 364038.26 | C28: =IF(A28="","",SUMIF($H$13:$H$372,A28,$K$13:$K$372)) -> 195240.45 | D28: =IF(A28="","",INDEX($M$13:$M$372,A28*12)) -> 1855125 | G28: =IF(16<=$B$6*12,16,"") -> 16 | H28: =IF(G28="","",ROUNDUP(G28/12,0)) -> 2 | I28: =IF(G28="","",M27) -> 4888608.4 | J28: =IF(G28="","",$E$5) -> 46606.559 | K28: =IF(G28="","",I28*$E$4/12) -> 38701.483 | L28: =IF(G28="","",J28-K28) -> 7905.076 | M28: =IF(G28="","",MAX(0,I28-L28)) -> 4880703.4
A29: =IF(17<=$B$6,17,"") -> 17 | B29: =IF(A29="","",SUMIF($H$13:$H$372,A29,$L$13:$L$372)) -> 400168.18 | C29: =IF(A29="","",SUMIF($H$13:$H$372,A29,$K$13:$K$372)) -> 159110.54 | D29: =IF(A29="","",INDEX($M$13:$M$372,A29*12)) -> 1454956.8 | G29: =IF(17<=$B$6*12,17,"") -> 17 | H29: =IF(G29="","",ROUNDUP(G29/12,0)) -> 2 | I29: =IF(G29="","",M28) -> 4880703.4 | J29: =IF(G29="","",$E$5) -> 46606.559 | K29: =IF(G29="","",I29*$E$4/12) -> 38638.902 | L29: =IF(G29="","",J29-K29) -> 7967.6578 | M29: =IF(G29="","",MAX(0,I29-L29)) -> 4872735.7
A30: =IF(18<=$B$6,18,"") -> 18 | B30: =IF(A30="","",SUMIF($H$13:$H$372,A30,$L$13:$L$372)) -> 439883.9 | C30: =IF(A30="","",SUMIF($H$13:$H$372,A30,$K$13:$K$372)) -> 119394.81 | D30: =IF(A30="","",INDEX($M$13:$M$372,A30*12)) -> 1015072.9 | G30: =IF(18<=$B$6*12,18,"") -> 18 | H30: =IF(G30="","",ROUNDUP(G30/12,0)) -> 2 | I30: =IF(G30="","",M29) -> 4872735.7 | J30: =IF(G30="","",$E$5) -> 46606.559 | K30: =IF(G30="","",I30*$E$4/12) -> 38575.824 | L30: =IF(G30="","",J30-K30) -> 8030.7351 | M30: =IF(G30="","",MAX(0,I30-L30)) -> 4864705
A31: =IF(19<=$B$6,19,"") -> 19 | B31: =IF(A31="","",SUMIF($H$13:$H$372,A31,$L$13:$L$372)) -> 483541.32 | C31: =IF(A31="","",SUMIF($H$13:$H$372,A31,$K$13:$K$372)) -> 75737.396 | D31: =IF(A31="","",INDEX($M$13:$M$372,A31*12)) -> 531531.62 | G31: =IF(19<=$B$6*12,19,"") -> 19 | H31: =IF(G31="","",ROUNDUP(G31/12,0)) -> 2 | I31: =IF(G31="","",M30) -> 4864705 | J31: =IF(G31="","",$E$5) -> 46606.559 | K31: =IF(G31="","",I31*$E$4/12) -> 38512.248 | L31: =IF(G31="","",J31-K31) -> 8094.3117 | M31: =IF(G31="","",MAX(0,I31-L31)) -> 4856610.7
A32: =IF(20<=$B$6,20,"") -> 20 | B32: =IF(A32="","",SUMIF($H$13:$H$372,A32,$L$13:$L$372)) -> 531531.62 | C32: =IF(A32="","",SUMIF($H$13:$H$372,A32,$K$13:$K$372)) -> 27747.089 | D32: =IF(A32="","",INDEX($M$13:$M$372,A32*12)) -> 1.6734703e-09 | G32: =IF(20<=$B$6*12,20,"") -> 20 | H32: =IF(G32="","",ROUNDUP(G32/12,0)) -> 2 | I32: =IF(G32="","",M31) -> 4856610.7 | J32: =IF(G32="","",$E$5) -> 46606.559 | K32: =IF(G32="","",I32*$E$4/12) -> 38448.168 | L32: =IF(G32="","",J32-K32) -> 8158.3917 | M32: =IF(G32="","",MAX(0,I32-L32)) -> 4848452.3
A33: =IF(21<=$B$6,21,"") | B33: =IF(A33="","",SUMIF($H$13:$H$372,A33,$L$13:$L$372)) | C33: =IF(A33="","",SUMIF($H$13:$H$372,A33,$K$13:$K$372)) | D33: =IF(A33="","",INDEX($M$13:$M$372,A33*12)) | G33: =IF(21<=$B$6*12,21,"") -> 21 | H33: =IF(G33="","",ROUNDUP(G33/12,0)) -> 2 | I33: =IF(G33="","",M32) -> 4848452.3 | J33: =IF(G33="","",$E$5) -> 46606.559 | K33: =IF(G33="","",I33*$E$4/12) -> 38383.58 | L33: =IF(G33="","",J33-K33) -> 8222.979 | M33: =IF(G33="","",MAX(0,I33-L33)) -> 4840229.3
A34: =IF(22<=$B$6,22,"") | B34: =IF(A34="","",SUMIF($H$13:$H$372,A34,$L$13:$L$372)) | C34: =IF(A34="","",SUMIF($H$13:$H$372,A34,$K$13:$K$372)) | D34: =IF(A34="","",INDEX($M$13:$M$372,A34*12)) | G34: =IF(22<=$B$6*12,22,"") -> 22 | H34: =IF(G34="","",ROUNDUP(G34/12,0)) -> 2 | I34: =IF(G34="","",M33) -> 4840229.3 | J34: =IF(G34="","",$E$5) -> 46606.559 | K34: =IF(G34="","",I34*$E$4/12) -> 38318.482 | L34: =IF(G34="","",J34-K34) -> 8288.0776 | M34: =IF(G34="","",MAX(0,I34-L34)) -> 4831941.2
A35: =IF(23<=$B$6,23,"") | B35: =IF(A35="","",SUMIF($H$13:$H$372,A35,$L$13:$L$372)) | C35: =IF(A35="","",SUMIF($H$13:$H$372,A35,$K$13:$K$372)) | D35: =IF(A35="","",INDEX($M$13:$M$372,A35*12)) | G35: =IF(23<=$B$6*12,23,"") -> 23 | H35: =IF(G35="","",ROUNDUP(G35/12,0)) -> 2 | I35: =IF(G35="","",M34) -> 4831941.2 | J35: =IF(G35="","",$E$5) -> 46606.559 | K35: =IF(G35="","",I35*$E$4/12) -> 38252.868 | L35: =IF(G35="","",J35-K35) -> 8353.6915 | M35: =IF(G35="","",MAX(0,I35-L35)) -> 4823587.5
A36: =IF(24<=$B$6,24,"") | B36: =IF(A36="","",SUMIF($H$13:$H$372,A36,$L$13:$L$372)) | C36: =IF(A36="","",SUMIF($H$13:$H$372,A36,$K$13:$K$372)) | D36: =IF(A36="","",INDEX($M$13:$M$372,A36*12)) | G36: =IF(24<=$B$6*12,24,"") -> 24 | H36: =IF(G36="","",ROUNDUP(G36/12,0)) -> 2 | I36: =IF(G36="","",M35) -> 4823587.5 | J36: =IF(G36="","",$E$5) -> 46606.559 | K36: =IF(G36="","",I36*$E$4/12) -> 38186.734 | L36: =IF(G36="","",J36-K36) -> 8419.8249 | M36: =IF(G36="","",MAX(0,I36-L36)) -> 4815167.7
A37: =IF(25<=$B$6,25,"") | B37: =IF(A37="","",SUMIF($H$13:$H$372,A37,$L$13:$L$372)) | C37: =IF(A37="","",SUMIF($H$13:$H$372,A37,$K$13:$K$372)) | D37: =IF(A37="","",INDEX($M$13:$M$372,A37*12)) | G37: =IF(25<=$B$6*12,25,"") -> 25 | H37: =IF(G37="","",ROUNDUP(G37/12,0)) -> 3 | I37: =IF(G37="","",M36) -> 4815167.7 | J37: =IF(G37="","",$E$5) -> 46606.559 | K37: =IF(G37="","",I37*$E$4/12) -> 38120.078 | L37: =IF(G37="","",J37-K37) -> 8486.4819 | M37: =IF(G37="","",MAX(0,I37-L37)) -> 4806681.2
A38: =IF(26<=$B$6,26,"") | B38: =IF(A38="","",SUMIF($H$13:$H$372,A38,$L$13:$L$372)) | C38: =IF(A38="","",SUMIF($H$13:$H$372,A38,$K$13:$K$372)) | D38: =IF(A38="","",INDEX($M$13:$M$372,A38*12)) | G38: =IF(26<=$B$6*12,26,"") -> 26 | H38: =IF(G38="","",ROUNDUP(G38/12,0)) -> 3 | I38: =IF(G38="","",M37) -> 4806681.2 | J38: =IF(G38="","",$E$5) -> 46606.559 | K38: =IF(G38="","",I38*$E$4/12) -> 38052.893 | L38: =IF(G38="","",J38-K38) -> 8553.6665 | M38: =IF(G38="","",MAX(0,I38-L38)) -> 4798127.5
A39: =IF(27<=$B$6,27,"") | B39: =IF(A39="","",SUMIF($H$13:$H$372,A39,$L$13:$L$372)) | C39: =IF(A39="","",SUMIF($H$13:$H$372,A39,$K$13:$K$372)) | D39: =IF(A39="","",INDEX($M$13:$M$372,A39*12)) | G39: =IF(27<=$B$6*12,27,"") -> 27 | H39: =IF(G39="","",ROUNDUP(G39/12,0)) -> 3 | I39: =IF(G39="","",M38) -> 4798127.5 | J39: =IF(G39="","",$E$5) -> 46606.559 | K39: =IF(G39="","",I39*$E$4/12) -> 37985.176 | L39: =IF(G39="","",J39-K39) -> 8621.383 | M39: =IF(G39="","",MAX(0,I39-L39)) -> 4789506.2
A40: =IF(28<=$B$6,28,"") | B40: =IF(A40="","",SUMIF($H$13:$H$372,A40,$L$13:$L$372)) | C40: =IF(A40="","",SUMIF($H$13:$H$372,A40,$K$13:$K$372)) | D40: =IF(A40="","",INDEX($M$13:$M$372,A40*12)) | G40: =IF(28<=$B$6*12,28,"") -> 28 | H40: =IF(G40="","",ROUNDUP(G40/12,0)) -> 3 | I40: =IF(G40="","",M39) -> 4789506.2 | J40: =IF(G40="","",$E$5) -> 46606.559 | K40: =IF(G40="","",I40*$E$4/12) -> 37916.924 | L40: =IF(G40="","",J40-K40) -> 8689.6356 | M40: =IF(G40="","",MAX(0,I40-L40)) -> 4780816.5
A41: =IF(29<=$B$6,29,"") | B41: =IF(A41="","",SUMIF($H$13:$H$372,A41,$L$13:$L$372)) | C41: =IF(A41="","",SUMIF($H$13:$H$372,A41,$K$13:$K$372)) | D41: =IF(A41="","",INDEX($M$13:$M$372,A41*12)) | G41: =IF(29<=$B$6*12,29,"") -> 29 | H41: =IF(G41="","",ROUNDUP(G41/12,0)) -> 3 | I41: =IF(G41="","",M40) -> 4780816.5 | J41: =IF(G41="","",$E$5) -> 46606.559 | K41: =IF(G41="","",I41*$E$4/12) -> 37848.131 | L41: =IF(G41="","",J41-K41) -> 8758.4286 | M41: =IF(G41="","",MAX(0,I41-L41)) -> 4772058.1
A42: =IF(30<=$B$6,30,"") | B42: =IF(A42="","",SUMIF($H$13:$H$372,A42,$L$13:$L$372)) | C42: =IF(A42="","",SUMIF($H$13:$H$372,A42,$K$13:$K$372)) | D42: =IF(A42="","",INDEX($M$13:$M$372,A42*12)) | G42: =IF(30<=$B$6*12,30,"") -> 30 | H42: =IF(G42="","",ROUNDUP(G42/12,0)) -> 3 | I42: =IF(G42="","",M41) -> 4772058.1 | J42: =IF(G42="","",$E$5) -> 46606.559 | K42: =IF(G42="","",I42*$E$4/12) -> 37778.793 | L42: =IF(G42="","",J42-K42) -> 8827.7662 | M42: =IF(G42="","",MAX(0,I42-L42)) -> 4763230.3
...
